Workbook

Sheet Summary
A1: Fair value summary: AAPL, MSFT, GOOGL, AMZN, QQQ, GLD
A2: Prices as of the 14 Oct 2026 close. Every figure links to the asset tabs. Blue = input you can change. Black = formula. Green = link to another tab. US$ billions unless stated; per-share values in US$.
A4: 10-year US Treasury yield | B4: 0.052 | C4: Approx. 5.2% on 13 to 14 Oct 2026 (Trading Economics, roic.ai). Update as needed.
A6: Ticker | B6: Name | C6: Price (US$) | D6: Bear | E6: Base | F6: Bull | G6: Fair value (30/50/20) | H6: Buy-below | I6: Price vs fair value | J6: Status | K6: Implied return (base) | L6: Return over Treasury | M6: Margin of safety
A7: AAPL | B7: Apple Inc. | C7: ='AAPL'!B5 | D7: ='AAPL'!B63 | E7: ='AAPL'!C63 | F7: ='AAPL'!D63 | G7: ='AAPL'!B66 | H7: ='AAPL'!B67 | I7: ='AAPL'!B69 | J7: ='AAPL'!B70 | K7: ='AAPL'!B72 | L7: =IF(ISNUMBER(K7),K7-$B$4,"n/a") | M7: ='AAPL'!B15
A8: MSFT | B8: Microsoft Corp. | C8: ='MSFT'!B5 | D8: ='MSFT'!B63 | E8: ='MSFT'!C63 | F8: ='MSFT'!D63 | G8: ='MSFT'!B66 | H8: ='MSFT'!B67 | I8: ='MSFT'!B69 | J8: ='MSFT'!B70 | K8: ='MSFT'!B72 | L8: =IF(ISNUMBER(K8),K8-$B$4,"n/a") | M8: ='MSFT'!B15
A9: GOOGL | B9: Alphabet Inc. (Class A) | C9: ='GOOGL'!B5 | D9: ='GOOGL'!B63 | E9: ='GOOGL'!C63 | F9: ='GOOGL'!D63 | G9: ='GOOGL'!B66 | H9: ='GOOGL'!B67 | I9: ='GOOGL'!B69 | J9: ='GOOGL'!B70 | K9: ='GOOGL'!B72 | L9: =IF(ISNUMBER(K9),K9-$B$4,"n/a") | M9: ='GOOGL'!B15
A10: AMZN | B10: Amazon.com Inc. | C10: ='AMZN'!B5 | D10: ='AMZN'!B63 | E10: ='AMZN'!C63 | F10: ='AMZN'!D63 | G10: ='AMZN'!B66 | H10: ='AMZN'!B67 | I10: ='AMZN'!B69 | J10: ='AMZN'!B70 | K10: ='AMZN'!B72 | L10: =IF(ISNUMBER(K10),K10-$B$4,"n/a") | M10: ='AMZN'!B15
A11: QQQ | B11: Invesco QQQ Trust | C11: ='QQQ'!B5 | D11: ='QQQ'!B55 | E11: ='QQQ'!C55 | F11: ='QQQ'!D55 | G11: ='QQQ'!B58 | H11: ='QQQ'!B59 | I11: ='QQQ'!B61 | J11: ='QQQ'!B62 | K11: ='QQQ'!B64 | L11: =IF(ISNUMBER(K11),K11-$B$4,"n/a") | M11: ='QQQ'!B10
A12: GLD | B12: SPDR Gold Shares (reference range) | C12: ='GLD'!B5 | D12: ='GLD'!B14 | E12: ='GLD'!C14 | F12: ='GLD'!D14 | G12: ='GLD'!B19 | H12: ='GLD'!B20 | I12: ='GLD'!B22 | J12: ='GLD'!B23 | K12: n/a | L12: n/a | M12: ='GLD'!B7
A14: How to read this: 'Price vs fair value' is price divided by the probability-weighted value, minus one. Positive means the price is above the estimated value.
A15: Status bands: Attractive = at or below the buy-below price. Potentially interesting = up to half the margin of safety below fair value. Little margin = up to fair value. Above = price exceeds fair value.
A16: Implied return = the annual return an investor earns from today's price if the base case plays out, compared with the 10-year Treasury yield.
A17: GLD has no cash flows. Its row is a scenario reference range built on judgement, not an intrinsic value. QQQ uses an earnings look-through model with weaker inputs.
A18: Required returns are set high relative to history because Treasury yields are at multi-year highs. Each tab has a sensitivity grid showing value at lower required returns.
A19: This is a framework for your own analysis, not personalised investment advice. Several inputs are estimates and are labelled as such on each tab.

Sheet AAPL
A1: AAPL: Apple Inc.
A2: Blue = input you can change. Black = formula. Green = link to another tab. US$ billions unless stated; per-share values in US$.
A4: 1. Inputs (market data as of 14 Oct 2026 close; financials from latest filings)
A5: Share price (US$) | B5: 342.96 | C5: Close 14 Oct 2026, StockAnalysis.com (S&P Global data)
A6: Shares outstanding (bn) | B6: 14.594 | C6: Apple 10-Q (quarter to 27 Jun 2026): 14.594bn shares at 17 Jul 2026
A7: TTM revenue ($bn) | B7: 466.8 | C7: TTM to Jun 2026: TTM FCF divided by the reported 29.28% FCF margin (StockAnalysis.com)
A8: TTM free cash flow ($bn) | B8: 136.683 | C8: TTM to Jun 2026, StockAnalysis.com / Alpha Spread: $136.7bn
A9: TTM stock-based compensation ($bn) | B9: 13.706 | C9: TTM to Jun 2026, StockAnalysis.com: $13.7bn
A10: Net cash / (debt) ($bn) | B10: 64.2 | C10: Apple 10-Q 27 Jun 2026: cash and securities $146.5bn less term debt $82.3bn
A11: Other assets at book value ($bn) | B11: 0 | C11: None
A12: Haircut applied to other assets | B12: 0 | C12: Judgement: private stakes valued at half of book
A13: Required annual return | B13: 0.09 | C13: 10-yr Treasury ~5.2% (Oct 2026) plus an equity premium of about 3.8 to 5.3 points
A14: Terminal growth rate | B14: 0.025 | C14: Below long-run nominal GDP growth
A15: Margin of safety | B15: 0.25 | C15: Wider for businesses whose free cash flow is currently depressed or uncertain
A16: Current SBC-adjusted FCF margin | B16: =(B8-B9)/B7 | C16: (FCF minus stock-based compensation) divided by revenue
A17: Adjusted net cash ($bn) | B17: =B10+B11*(1-B12)
A19: 2. Scenario assumptions
B20: Bear | C20: Base | D20: Bull
A21: Revenue growth, year 1 | B21: 0.06 | C21: 0.09 | D21: 0.12
A22: Revenue growth, year 10 | B22: 0.03 | C22: 0.04 | D22: 0.05
A23: Target SBC-adjusted FCF margin | B23: 0.225 | C23: 0.245 | D23: 0.265
A24: Probability | B24: 0.3 | C24: 0.5 | D24: 0.2 | E24: =IF(ROUND(SUM(B24:D24),6)=1,"OK: sums to 100%","Probabilities must sum to 100%")
A25: Years to reach target margin | B25: 5 | C25: Growth fades in a straight line from year 1 to year 10; margin moves in a straight line to target.
A27: 3. Ten-year projection (growth fades linearly; value of years beyond year 10 is captured by the terminal value)
A28: Bear case | C28: Y1 | D28: Y2 | E28: Y3 | F28: Y4 | G28: Y5 | H28: Y6 | I28: Y7 | J28: Y8 | K28: Y9 | L28: Y10
A29: Year index | C29: 1 | D29: 2 | E29: 3 | F29: 4 | G29: 5 | H29: 6 | I29: 7 | J29: 8 | K29: 9 | L29: 10
A30: Revenue growth | C30: =$B$21+($B$22-$B$21)*(C29-1)/9 | D30: =$B$21+($B$22-$B$21)*(D29-1)/9 | E30: =$B$21+($B$22-$B$21)*(E29-1)/9 | F30: =$B$21+($B$22-$B$21)*(F29-1)/9 | G30: =$B$21+($B$22-$B$21)*(G29-1)/9 | H30: =$B$21+($B$22-$B$21)*(H29-1)/9 | I30: =$B$21+($B$22-$B$21)*(I29-1)/9 | J30: =$B$21+($B$22-$B$21)*(J29-1)/9 | ... L30: =$B$21+($B$22-$B$21)*(L29-1)/9
A31: Revenue ($bn) | C31: =$B$7*(1+C30) | D31: =C31*(1+D30) | E31: =D31*(1+E30) | F31: =E31*(1+F30) | G31: =F31*(1+G30) | H31: =G31*(1+H30) | I31: =H31*(1+I30) | J31: =I31*(1+J30) | K31: =J31*(1+K30) | L31: =K31*(1+L30)
A32: SBC-adjusted FCF margin | C32: =$B$16+($B$23-$B$16)*MIN(C29,$B$25)/$B$25 | D32: =$B$16+($B$23-$B$16)*MIN(D29,$B$25)/$B$25 | E32: =$B$16+($B$23-$B$16)*MIN(E29,$B$25)/$B$25 | F32: =$B$16+($B$23-$B$16)*MIN(F29,$B$25)/$B$25 | G32: =$B$16+($B$23-$B$16)*MIN(G29,$B$25)/$B$25 | H32: =$B$16+($B$23-$B$16)*MIN(H29,$B$25)/$B$25 | I32: =$B$16+($B$23-$B$16)*MIN(I29,$B$25)/$B$25 | J32: =$B$16+($B$23-$B$16)*MIN(J29,$B$25)/$B$25 | ... L32: =$B$16+($B$23-$B$16)*MIN(L29,$B$25)/$B$25
A33: SBC-adjusted FCF ($bn) | C33: =C31*C32 | D33: =D31*D32 | E33: =E31*E32 | F33: =F31*F32 | G33: =G31*G32 | H33: =H31*H32 | I33: =I31*I32 | J33: =J31*J32 | ... L33: =L31*L32
A34: Discount factor | C34: =1/(1+$B$13)^C29 | D34: =1/(1+$B$13)^D29 | E34: =1/(1+$B$13)^E29 | F34: =1/(1+$B$13)^F29 | G34: =1/(1+$B$13)^G29 | H34: =1/(1+$B$13)^H29 | I34: =1/(1+$B$13)^I29 | J34: =1/(1+$B$13)^J29 | ... L34: =1/(1+$B$13)^L29
A35: Present value of FCF ($bn) | C35: =C33*C34 | D35: =D33*D34 | E35: =E33*E34 | F35: =F33*F34 | G35: =G33*G34 | H35: =H33*H34 | I35: =I33*I34 | J35: =J33*J34 | ... L35: =L33*L34
A37: Base case | C37: Y1 | D37: Y2 | E37: Y3 | F37: Y4 | G37: Y5 | H37: Y6 | I37: Y7 | J37: Y8 | K37: Y9 | L37: Y10
A38: Year index | C38: 1 | D38: 2 | E38: 3 | F38: 4 | G38: 5 | H38: 6 | I38: 7 | J38: 8 | K38: 9 | L38: 10
A39: Revenue growth | C39: =$C$21+($C$22-$C$21)*(C38-1)/9 | D39: =$C$21+($C$22-$C$21)*(D38-1)/9 | E39: =$C$21+($C$22-$C$21)*(E38-1)/9 | F39: =$C$21+($C$22-$C$21)*(F38-1)/9 | G39: =$C$21+($C$22-$C$21)*(G38-1)/9 | H39: =$C$21+($C$22-$C$21)*(H38-1)/9 | I39: =$C$21+($C$22-$C$21)*(I38-1)/9 | J39: =$C$21+($C$22-$C$21)*(J38-1)/9 | ... L39: =$C$21+($C$22-$C$21)*(L38-1)/9
A40: Revenue ($bn) | C40: =$B$7*(1+C39) | D40: =C40*(1+D39) | E40: =D40*(1+E39) | F40: =E40*(1+F39) | G40: =F40*(1+G39) | H40: =G40*(1+H39) | I40: =H40*(1+I39) | J40: =I40*(1+J39) | K40: =J40*(1+K39) | L40: =K40*(1+L39)
A41: SBC-adjusted FCF margin | C41: =$B$16+($C$23-$B$16)*MIN(C38,$B$25)/$B$25 | D41: =$B$16+($C$23-$B$16)*MIN(D38,$B$25)/$B$25 | E41: =$B$16+($C$23-$B$16)*MIN(E38,$B$25)/$B$25 | F41: =$B$16+($C$23-$B$16)*MIN(F38,$B$25)/$B$25 | G41: =$B$16+($C$23-$B$16)*MIN(G38,$B$25)/$B$25 | H41: =$B$16+($C$23-$B$16)*MIN(H38,$B$25)/$B$25 | I41: =$B$16+($C$23-$B$16)*MIN(I38,$B$25)/$B$25 | J41: =$B$16+($C$23-$B$16)*MIN(J38,$B$25)/$B$25 | ... L41: =$B$16+($C$23-$B$16)*MIN(L38,$B$25)/$B$25
A42: SBC-adjusted FCF ($bn) | C42: =C40*C41 | D42: =D40*D41 | E42: =E40*E41 | F42: =F40*F41 | G42: =G40*G41 | H42: =H40*H41 | I42: =I40*I41 | J42: =J40*J41 | ... L42: =L40*L41
A43: Discount factor | C43: =1/(1+$B$13)^C38 | D43: =1/(1+$B$13)^D38 | E43: =1/(1+$B$13)^E38 | F43: =1/(1+$B$13)^F38 | G43: =1/(1+$B$13)^G38 | H43: =1/(1+$B$13)^H38 | I43: =1/(1+$B$13)^I38 | J43: =1/(1+$B$13)^J38 | ... L43: =1/(1+$B$13)^L38
A44: Present value of FCF ($bn) | C44: =C42*C43 | D44: =D42*D43 | E44: =E42*E43 | F44: =F42*F43 | G44: =G42*G43 | H44: =H42*H43 | I44: =I42*I43 | J44: =J42*J43 | ... L44: =L42*L43
...

Sheet MSFT
A1: MSFT: Microsoft Corp.
A2: Blue = input you can change. Black = formula. Green = link to another tab. US$ billions unless stated; per-share values in US$.
A4: 1. Inputs (market data as of 14 Oct 2026 close; financials from latest filings)
A5: Share price (US$) | B5: 533.69 | C5: Close 14 Oct 2026, StockAnalysis.com (S&P Global data)
A6: Shares outstanding (bn) | B6: 7.43 | C6: Microsoft 10-Q: 7.428bn shares at 23 Apr 2026
A7: TTM revenue ($bn) | B7: 331.3 | C7: FY2026 (to 30 Jun 2026): revenue just over $331bn, Q4 earnings call
A8: TTM free cash flow ($bn) | B8: 66.987 | C8: FY2026: operating cash flow $182.9bn less capex $115.9bn (StockAnalysis.com)
A9: TTM stock-based compensation ($bn) | B9: 12.405 | C9: FY2026, StockAnalysis.com: $12.4bn
A10: Net cash / (debt) ($bn) | B10: 20 | C10: StockAnalysis.com, 30 Jun 2026: cash $76.8bn less debt $56.8bn. Finance leases partly excluded.
A11: Other assets at book value ($bn) | B11: 0 | C11: None
A12: Haircut applied to other assets | B12: 0 | C12: Judgement: private stakes valued at half of book
A13: Required annual return | B13: 0.09 | C13: 10-yr Treasury ~5.2% (Oct 2026) plus an equity premium of about 3.8 to 5.3 points
A14: Terminal growth rate | B14: 0.025 | C14: Below long-run nominal GDP growth
A15: Margin of safety | B15: 0.25 | C15: Wider for businesses whose free cash flow is currently depressed or uncertain
A16: Current SBC-adjusted FCF margin | B16: =(B8-B9)/B7 | C16: (FCF minus stock-based compensation) divided by revenue
A17: Adjusted net cash ($bn) | B17: =B10+B11*(1-B12)
A19: 2. Scenario assumptions
B20: Bear | C20: Base | D20: Bull
A21: Revenue growth, year 1 | B21: 0.12 | C21: 0.17 | D21: 0.2
A22: Revenue growth, year 10 | B22: 0.035 | C22: 0.05 | D22: 0.06
A23: Target SBC-adjusted FCF margin | B23: 0.18 | C23: 0.25 | D23: 0.29
A24: Probability | B24: 0.3 | C24: 0.5 | D24: 0.2 | E24: =IF(ROUND(SUM(B24:D24),6)=1,"OK: sums to 100%","Probabilities must sum to 100%")
A25: Years to reach target margin | B25: 5 | C25: Growth fades in a straight line from year 1 to year 10; margin moves in a straight line to target.
A27: 3. Ten-year projection (growth fades linearly; value of years beyond year 10 is captured by the terminal value)
A28: Bear case | C28: Y1 | D28: Y2 | E28: Y3 | F28: Y4 | G28: Y5 | H28: Y6 | I28: Y7 | J28: Y8 | K28: Y9 | L28: Y10
A29: Year index | C29: 1 | D29: 2 | E29: 3 | F29: 4 | G29: 5 | H29: 6 | I29: 7 | J29: 8 | K29: 9 | L29: 10
A30: Revenue growth | C30: =$B$21+($B$22-$B$21)*(C29-1)/9 | D30: =$B$21+($B$22-$B$21)*(D29-1)/9 | E30: =$B$21+($B$22-$B$21)*(E29-1)/9 | F30: =$B$21+($B$22-$B$21)*(F29-1)/9 | G30: =$B$21+($B$22-$B$21)*(G29-1)/9 | H30: =$B$21+($B$22-$B$21)*(H29-1)/9 | I30: =$B$21+($B$22-$B$21)*(I29-1)/9 | J30: =$B$21+($B$22-$B$21)*(J29-1)/9 | ... L30: =$B$21+($B$22-$B$21)*(L29-1)/9
A31: Revenue ($bn) | C31: =$B$7*(1+C30) | D31: =C31*(1+D30) | E31: =D31*(1+E30) | F31: =E31*(1+F30) | G31: =F31*(1+G30) | H31: =G31*(1+H30) | I31: =H31*(1+I30) | J31: =I31*(1+J30) | K31: =J31*(1+K30) | L31: =K31*(1+L30)
A32: SBC-adjusted FCF margin | C32: =$B$16+($B$23-$B$16)*MIN(C29,$B$25)/$B$25 | D32: =$B$16+($B$23-$B$16)*MIN(D29,$B$25)/$B$25 | E32: =$B$16+($B$23-$B$16)*MIN(E29,$B$25)/$B$25 | F32: =$B$16+($B$23-$B$16)*MIN(F29,$B$25)/$B$25 | G32: =$B$16+($B$23-$B$16)*MIN(G29,$B$25)/$B$25 | H32: =$B$16+($B$23-$B$16)*MIN(H29,$B$25)/$B$25 | I32: =$B$16+($B$23-$B$16)*MIN(I29,$B$25)/$B$25 | J32: =$B$16+($B$23-$B$16)*MIN(J29,$B$25)/$B$25 | ... L32: =$B$16+($B$23-$B$16)*MIN(L29,$B$25)/$B$25
A33: SBC-adjusted FCF ($bn) | C33: =C31*C32 | D33: =D31*D32 | E33: =E31*E32 | F33: =F31*F32 | G33: =G31*G32 | H33: =H31*H32 | I33: =I31*I32 | J33: =J31*J32 | ... L33: =L31*L32
A34: Discount factor | C34: =1/(1+$B$13)^C29 | D34: =1/(1+$B$13)^D29 | E34: =1/(1+$B$13)^E29 | F34: =1/(1+$B$13)^F29 | G34: =1/(1+$B$13)^G29 | H34: =1/(1+$B$13)^H29 | I34: =1/(1+$B$13)^I29 | J34: =1/(1+$B$13)^J29 | ... L34: =1/(1+$B$13)^L29
A35: Present value of FCF ($bn) | C35: =C33*C34 | D35: =D33*D34 | E35: =E33*E34 | F35: =F33*F34 | G35: =G33*G34 | H35: =H33*H34 | I35: =I33*I34 | J35: =J33*J34 | ... L35: =L33*L34
A37: Base case | C37: Y1 | D37: Y2 | E37: Y3 | F37: Y4 | G37: Y5 | H37: Y6 | I37: Y7 | J37: Y8 | K37: Y9 | L37: Y10
A38: Year index | C38: 1 | D38: 2 | E38: 3 | F38: 4 | G38: 5 | H38: 6 | I38: 7 | J38: 8 | K38: 9 | L38: 10
A39: Revenue growth | C39: =$C$21+($C$22-$C$21)*(C38-1)/9 | D39: =$C$21+($C$22-$C$21)*(D38-1)/9 | E39: =$C$21+($C$22-$C$21)*(E38-1)/9 | F39: =$C$21+($C$22-$C$21)*(F38-1)/9 | G39: =$C$21+($C$22-$C$21)*(G38-1)/9 | H39: =$C$21+($C$22-$C$21)*(H38-1)/9 | I39: =$C$21+($C$22-$C$21)*(I38-1)/9 | J39: =$C$21+($C$22-$C$21)*(J38-1)/9 | ... L39: =$C$21+($C$22-$C$21)*(L38-1)/9
A40: Revenue ($bn) | C40: =$B$7*(1+C39) | D40: =C40*(1+D39) | E40: =D40*(1+E39) | F40: =E40*(1+F39) | G40: =F40*(1+G39) | H40: =G40*(1+H39) | I40: =H40*(1+I39) | J40: =I40*(1+J39) | K40: =J40*(1+K39) | L40: =K40*(1+L39)
A41: SBC-adjusted FCF margin | C41: =$B$16+($C$23-$B$16)*MIN(C38,$B$25)/$B$25 | D41: =$B$16+($C$23-$B$16)*MIN(D38,$B$25)/$B$25 | E41: =$B$16+($C$23-$B$16)*MIN(E38,$B$25)/$B$25 | F41: =$B$16+($C$23-$B$16)*MIN(F38,$B$25)/$B$25 | G41: =$B$16+($C$23-$B$16)*MIN(G38,$B$25)/$B$25 | H41: =$B$16+($C$23-$B$16)*MIN(H38,$B$25)/$B$25 | I41: =$B$16+($C$23-$B$16)*MIN(I38,$B$25)/$B$25 | J41: =$B$16+($C$23-$B$16)*MIN(J38,$B$25)/$B$25 | ... L41: =$B$16+($C$23-$B$16)*MIN(L38,$B$25)/$B$25
A42: SBC-adjusted FCF ($bn) | C42: =C40*C41 | D42: =D40*D41 | E42: =E40*E41 | F42: =F40*F41 | G42: =G40*G41 | H42: =H40*H41 | I42: =I40*I41 | J42: =J40*J41 | ... L42: =L40*L41
A43: Discount factor | C43: =1/(1+$B$13)^C38 | D43: =1/(1+$B$13)^D38 | E43: =1/(1+$B$13)^E38 | F43: =1/(1+$B$13)^F38 | G43: =1/(1+$B$13)^G38 | H43: =1/(1+$B$13)^H38 | I43: =1/(1+$B$13)^I38 | J43: =1/(1+$B$13)^J38 | ... L43: =1/(1+$B$13)^L38
A44: Present value of FCF ($bn) | C44: =C42*C43 | D44: =D42*D43 | E44: =E42*E43 | F44: =F42*F43 | G44: =G42*G43 | H44: =H42*H43 | I44: =I42*I43 | J44: =J42*J43 | ... L44: =L42*L43
...

Sheet GOOGL
A1: GOOGL: Alphabet Inc. (Class A)
A2: Blue = input you can change. Black = formula. Green = link to another tab. US$ billions unless stated; per-share values in US$.
A4: 1. Inputs (market data as of 14 Oct 2026 close; financials from latest filings)
A5: Share price (US$) | B5: 347.64 | C5: Close 14 Oct 2026, StockAnalysis.com (S&P Global data)
A6: Shares outstanding (bn) | B6: 12.23 | C6: Alphabet 10-Q: 12.23bn shares across A, B and C at 15 Jul 2026 (after the June equity raise)
A7: TTM revenue ($bn) | B7: 445.8 | C7: ESTIMATE: sum of the last four quarters (Q2 2026 $119.8bn, Q1 $109.9bn, Q4 and Q3 2025 approximated)
A8: TTM free cash flow ($bn) | B8: 53.273 | C8: Alphabet Q2 2026 release: TTM free cash flow $53.3bn (operating cash flow $185.7bn less capex $132.4bn)
A9: TTM stock-based compensation ($bn) | B9: 24.5 | C9: ESTIMATE: about 5.5% of revenue; not verified against the filing
A10: Net cash / (debt) ($bn) | B10: 129.7 | C10: StockAnalysis.com, 30 Jun 2026: cash and securities $242.5bn less debt $112.8bn
A11: Other assets at book value ($bn) | B11: 131.4 | C11: Alphabet 10-Q: long-term (non-marketable) investments $131.5bn at 30 Jun 2026
A12: Haircut applied to other assets | B12: 0.5 | C12: Judgement: private stakes valued at half of book
A13: Required annual return | B13: 0.1 | C13: 10-yr Treasury ~5.2% (Oct 2026) plus an equity premium of about 3.8 to 5.3 points
A14: Terminal growth rate | B14: 0.025 | C14: Below long-run nominal GDP growth
A15: Margin of safety | B15: 0.3 | C15: Wider for businesses whose free cash flow is currently depressed or uncertain
A16: Current SBC-adjusted FCF margin | B16: =(B8-B9)/B7 | C16: (FCF minus stock-based compensation) divided by revenue
A17: Adjusted net cash ($bn) | B17: =B10+B11*(1-B12)
A19: 2. Scenario assumptions
B20: Bear | C20: Base | D20: Bull
A21: Revenue growth, year 1 | B21: 0.14 | C21: 0.2 | D21: 0.24
A22: Revenue growth, year 10 | B22: 0.035 | C22: 0.05 | D22: 0.06
A23: Target SBC-adjusted FCF margin | B23: 0.13 | C23: 0.19 | D23: 0.24
A24: Probability | B24: 0.3 | C24: 0.5 | D24: 0.2 | E24: =IF(ROUND(SUM(B24:D24),6)=1,"OK: sums to 100%","Probabilities must sum to 100%")
A25: Years to reach target margin | B25: 5 | C25: Growth fades in a straight line from year 1 to year 10; margin moves in a straight line to target.
A27: 3. Ten-year projection (growth fades linearly; value of years beyond year 10 is captured by the terminal value)
A28: Bear case | C28: Y1 | D28: Y2 | E28: Y3 | F28: Y4 | G28: Y5 | H28: Y6 | I28: Y7 | J28: Y8 | K28: Y9 | L28: Y10
A29: Year index | C29: 1 | D29: 2 | E29: 3 | F29: 4 | G29: 5 | H29: 6 | I29: 7 | J29: 8 | K29: 9 | L29: 10
A30: Revenue growth | C30: =$B$21+($B$22-$B$21)*(C29-1)/9 | D30: =$B$21+($B$22-$B$21)*(D29-1)/9 | E30: =$B$21+($B$22-$B$21)*(E29-1)/9 | F30: =$B$21+($B$22-$B$21)*(F29-1)/9 | G30: =$B$21+($B$22-$B$21)*(G29-1)/9 | H30: =$B$21+($B$22-$B$21)*(H29-1)/9 | I30: =$B$21+($B$22-$B$21)*(I29-1)/9 | J30: =$B$21+($B$22-$B$21)*(J29-1)/9 | ... L30: =$B$21+($B$22-$B$21)*(L29-1)/9
A31: Revenue ($bn) | C31: =$B$7*(1+C30) | D31: =C31*(1+D30) | E31: =D31*(1+E30) | F31: =E31*(1+F30) | G31: =F31*(1+G30) | H31: =G31*(1+H30) | I31: =H31*(1+I30) | J31: =I31*(1+J30) | K31: =J31*(1+K30) | L31: =K31*(1+L30)
A32: SBC-adjusted FCF margin | C32: =$B$16+($B$23-$B$16)*MIN(C29,$B$25)/$B$25 | D32: =$B$16+($B$23-$B$16)*MIN(D29,$B$25)/$B$25 | E32: =$B$16+($B$23-$B$16)*MIN(E29,$B$25)/$B$25 | F32: =$B$16+($B$23-$B$16)*MIN(F29,$B$25)/$B$25 | G32: =$B$16+($B$23-$B$16)*MIN(G29,$B$25)/$B$25 | H32: =$B$16+($B$23-$B$16)*MIN(H29,$B$25)/$B$25 | I32: =$B$16+($B$23-$B$16)*MIN(I29,$B$25)/$B$25 | J32: =$B$16+($B$23-$B$16)*MIN(J29,$B$25)/$B$25 | ... L32: =$B$16+($B$23-$B$16)*MIN(L29,$B$25)/$B$25
A33: SBC-adjusted FCF ($bn) | C33: =C31*C32 | D33: =D31*D32 | E33: =E31*E32 | F33: =F31*F32 | G33: =G31*G32 | H33: =H31*H32 | I33: =I31*I32 | J33: =J31*J32 | ... L33: =L31*L32
A34: Discount factor | C34: =1/(1+$B$13)^C29 | D34: =1/(1+$B$13)^D29 | E34: =1/(1+$B$13)^E29 | F34: =1/(1+$B$13)^F29 | G34: =1/(1+$B$13)^G29 | H34: =1/(1+$B$13)^H29 | I34: =1/(1+$B$13)^I29 | J34: =1/(1+$B$13)^J29 | ... L34: =1/(1+$B$13)^L29
A35: Present value of FCF ($bn) | C35: =C33*C34 | D35: =D33*D34 | E35: =E33*E34 | F35: =F33*F34 | G35: =G33*G34 | H35: =H33*H34 | I35: =I33*I34 | J35: =J33*J34 | ... L35: =L33*L34
A37: Base case | C37: Y1 | D37: Y2 | E37: Y3 | F37: Y4 | G37: Y5 | H37: Y6 | I37: Y7 | J37: Y8 | K37: Y9 | L37: Y10
A38: Year index | C38: 1 | D38: 2 | E38: 3 | F38: 4 | G38: 5 | H38: 6 | I38: 7 | J38: 8 | K38: 9 | L38: 10
A39: Revenue growth | C39: =$C$21+($C$22-$C$21)*(C38-1)/9 | D39: =$C$21+($C$22-$C$21)*(D38-1)/9 | E39: =$C$21+($C$22-$C$21)*(E38-1)/9 | F39: =$C$21+($C$22-$C$21)*(F38-1)/9 | G39: =$C$21+($C$22-$C$21)*(G38-1)/9 | H39: =$C$21+($C$22-$C$21)*(H38-1)/9 | I39: =$C$21+($C$22-$C$21)*(I38-1)/9 | J39: =$C$21+($C$22-$C$21)*(J38-1)/9 | ... L39: =$C$21+($C$22-$C$21)*(L38-1)/9
A40: Revenue ($bn) | C40: =$B$7*(1+C39) | D40: =C40*(1+D39) | E40: =D40*(1+E39) | F40: =E40*(1+F39) | G40: =F40*(1+G39) | H40: =G40*(1+H39) | I40: =H40*(1+I39) | J40: =I40*(1+J39) | K40: =J40*(1+K39) | L40: =K40*(1+L39)
A41: SBC-adjusted FCF margin | C41: =$B$16+($C$23-$B$16)*MIN(C38,$B$25)/$B$25 | D41: =$B$16+($C$23-$B$16)*MIN(D38,$B$25)/$B$25 | E41: =$B$16+($C$23-$B$16)*MIN(E38,$B$25)/$B$25 | F41: =$B$16+($C$23-$B$16)*MIN(F38,$B$25)/$B$25 | G41: =$B$16+($C$23-$B$16)*MIN(G38,$B$25)/$B$25 | H41: =$B$16+($C$23-$B$16)*MIN(H38,$B$25)/$B$25 | I41: =$B$16+($C$23-$B$16)*MIN(I38,$B$25)/$B$25 | J41: =$B$16+($C$23-$B$16)*MIN(J38,$B$25)/$B$25 | ... L41: =$B$16+($C$23-$B$16)*MIN(L38,$B$25)/$B$25
A42: SBC-adjusted FCF ($bn) | C42: =C40*C41 | D42: =D40*D41 | E42: =E40*E41 | F42: =F40*F41 | G42: =G40*G41 | H42: =H40*H41 | I42: =I40*I41 | J42: =J40*J41 | ... L42: =L40*L41
A43: Discount factor | C43: =1/(1+$B$13)^C38 | D43: =1/(1+$B$13)^D38 | E43: =1/(1+$B$13)^E38 | F43: =1/(1+$B$13)^F38 | G43: =1/(1+$B$13)^G38 | H43: =1/(1+$B$13)^H38 | I43: =1/(1+$B$13)^I38 | J43: =1/(1+$B$13)^J38 | ... L43: =1/(1+$B$13)^L38
A44: Present value of FCF ($bn) | C44: =C42*C43 | D44: =D42*D43 | E44: =E42*E43 | F44: =F42*F43 | G44: =G42*G43 | H44: =H42*H43 | I44: =I42*I43 | J44: =J42*J43 | ... L44: =L42*L43
...

Sheet AMZN
A1: AMZN: Amazon.com Inc.
A2: Blue = input you can change. Black = formula. Green = link to another tab. US$ billions unless stated; per-share values in US$.
A4: 1. Inputs (market data as of 14 Oct 2026 close; financials from latest filings)
A5: Share price (US$) | B5: 254.08 | C5: Close 14 Oct 2026, StockAnalysis.com (S&P Global data)
A6: Shares outstanding (bn) | B6: 10.786 | C6: Amazon 10-Q: 10.786bn shares at 22 Jul 2026
A7: TTM revenue ($bn) | B7: 775.7 | C7: Q2 2026 release: North America $453.7bn + International $173.6bn + AWS $148.4bn (TTM)
A8: TTM free cash flow ($bn) | B8: -7.604 | C8: Amazon Q2 2026 release: TTM free cash flow outflow of $7.6bn
A9: TTM stock-based compensation ($bn) | B9: 22 | C9: ESTIMATE: about $22bn a year; not verified against the filing
A10: Net cash / (debt) ($bn) | B10: -100.2 | C10: StockAnalysis.com, 30 Jun 2026: cash $123.0bn less total debt $223.2bn including leases
A11: Other assets at book value ($bn) | B11: 0 | C11: None. The Anthropic stake is not valued, so this is upside not counted.
A12: Haircut applied to other assets | B12: 0 | C12: Judgement: private stakes valued at half of book
A13: Required annual return | B13: 0.105 | C13: 10-yr Treasury ~5.2% (Oct 2026) plus an equity premium of about 3.8 to 5.3 points
A14: Terminal growth rate | B14: 0.025 | C14: Below long-run nominal GDP growth
A15: Margin of safety | B15: 0.3 | C15: Wider for businesses whose free cash flow is currently depressed or uncertain
A16: Current SBC-adjusted FCF margin | B16: =(B8-B9)/B7 | C16: (FCF minus stock-based compensation) divided by revenue
A17: Adjusted net cash ($bn) | B17: =B10+B11*(1-B12)
A19: 2. Scenario assumptions
B20: Bear | C20: Base | D20: Bull
A21: Revenue growth, year 1 | B21: 0.09 | C21: 0.13 | D21: 0.16
A22: Revenue growth, year 10 | B22: 0.035 | C22: 0.05 | D22: 0.06
A23: Target SBC-adjusted FCF margin | B23: 0.05 | C23: 0.085 | D23: 0.12
A24: Probability | B24: 0.3 | C24: 0.5 | D24: 0.2 | E24: =IF(ROUND(SUM(B24:D24),6)=1,"OK: sums to 100%","Probabilities must sum to 100%")
A25: Years to reach target margin | B25: 5 | C25: Growth fades in a straight line from year 1 to year 10; margin moves in a straight line to target.
A27: 3. Ten-year projection (growth fades linearly; value of years beyond year 10 is captured by the terminal value)
A28: Bear case | C28: Y1 | D28: Y2 | E28: Y3 | F28: Y4 | G28: Y5 | H28: Y6 | I28: Y7 | J28: Y8 | K28: Y9 | L28: Y10
A29: Year index | C29: 1 | D29: 2 | E29: 3 | F29: 4 | G29: 5 | H29: 6 | I29: 7 | J29: 8 | K29: 9 | L29: 10
A30: Revenue growth | C30: =$B$21+($B$22-$B$21)*(C29-1)/9 | D30: =$B$21+($B$22-$B$21)*(D29-1)/9 | E30: =$B$21+($B$22-$B$21)*(E29-1)/9 | F30: =$B$21+($B$22-$B$21)*(F29-1)/9 | G30: =$B$21+($B$22-$B$21)*(G29-1)/9 | H30: =$B$21+($B$22-$B$21)*(H29-1)/9 | I30: =$B$21+($B$22-$B$21)*(I29-1)/9 | J30: =$B$21+($B$22-$B$21)*(J29-1)/9 | ... L30: =$B$21+($B$22-$B$21)*(L29-1)/9
A31: Revenue ($bn) | C31: =$B$7*(1+C30) | D31: =C31*(1+D30) | E31: =D31*(1+E30) | F31: =E31*(1+F30) | G31: =F31*(1+G30) | H31: =G31*(1+H30) | I31: =H31*(1+I30) | J31: =I31*(1+J30) | K31: =J31*(1+K30) | L31: =K31*(1+L30)
A32: SBC-adjusted FCF margin | C32: =$B$16+($B$23-$B$16)*MIN(C29,$B$25)/$B$25 | D32: =$B$16+($B$23-$B$16)*MIN(D29,$B$25)/$B$25 | E32: =$B$16+($B$23-$B$16)*MIN(E29,$B$25)/$B$25 | F32: =$B$16+($B$23-$B$16)*MIN(F29,$B$25)/$B$25 | G32: =$B$16+($B$23-$B$16)*MIN(G29,$B$25)/$B$25 | H32: =$B$16+($B$23-$B$16)*MIN(H29,$B$25)/$B$25 | I32: =$B$16+($B$23-$B$16)*MIN(I29,$B$25)/$B$25 | J32: =$B$16+($B$23-$B$16)*MIN(J29,$B$25)/$B$25 | ... L32: =$B$16+($B$23-$B$16)*MIN(L29,$B$25)/$B$25
A33: SBC-adjusted FCF ($bn) | C33: =C31*C32 | D33: =D31*D32 | E33: =E31*E32 | F33: =F31*F32 | G33: =G31*G32 | H33: =H31*H32 | I33: =I31*I32 | J33: =J31*J32 | ... L33: =L31*L32
A34: Discount factor | C34: =1/(1+$B$13)^C29 | D34: =1/(1+$B$13)^D29 | E34: =1/(1+$B$13)^E29 | F34: =1/(1+$B$13)^F29 | G34: =1/(1+$B$13)^G29 | H34: =1/(1+$B$13)^H29 | I34: =1/(1+$B$13)^I29 | J34: =1/(1+$B$13)^J29 | ... L34: =1/(1+$B$13)^L29
A35: Present value of FCF ($bn) | C35: =C33*C34 | D35: =D33*D34 | E35: =E33*E34 | F35: =F33*F34 | G35: =G33*G34 | H35: =H33*H34 | I35: =I33*I34 | J35: =J33*J34 | ... L35: =L33*L34
A37: Base case | C37: Y1 | D37: Y2 | E37: Y3 | F37: Y4 | G37: Y5 | H37: Y6 | I37: Y7 | J37: Y8 | K37: Y9 | L37: Y10
A38: Year index | C38: 1 | D38: 2 | E38: 3 | F38: 4 | G38: 5 | H38: 6 | I38: 7 | J38: 8 | K38: 9 | L38: 10
A39: Revenue growth | C39: =$C$21+($C$22-$C$21)*(C38-1)/9 | D39: =$C$21+($C$22-$C$21)*(D38-1)/9 | E39: =$C$21+($C$22-$C$21)*(E38-1)/9 | F39: =$C$21+($C$22-$C$21)*(F38-1)/9 | G39: =$C$21+($C$22-$C$21)*(G38-1)/9 | H39: =$C$21+($C$22-$C$21)*(H38-1)/9 | I39: =$C$21+($C$22-$C$21)*(I38-1)/9 | J39: =$C$21+($C$22-$C$21)*(J38-1)/9 | ... L39: =$C$21+($C$22-$C$21)*(L38-1)/9
A40: Revenue ($bn) | C40: =$B$7*(1+C39) | D40: =C40*(1+D39) | E40: =D40*(1+E39) | F40: =E40*(1+F39) | G40: =F40*(1+G39) | H40: =G40*(1+H39) | I40: =H40*(1+I39) | J40: =I40*(1+J39) | K40: =J40*(1+K39) | L40: =K40*(1+L39)
A41: SBC-adjusted FCF margin | C41: =$B$16+($C$23-$B$16)*MIN(C38,$B$25)/$B$25 | D41: =$B$16+($C$23-$B$16)*MIN(D38,$B$25)/$B$25 | E41: =$B$16+($C$23-$B$16)*MIN(E38,$B$25)/$B$25 | F41: =$B$16+($C$23-$B$16)*MIN(F38,$B$25)/$B$25 | G41: =$B$16+($C$23-$B$16)*MIN(G38,$B$25)/$B$25 | H41: =$B$16+($C$23-$B$16)*MIN(H38,$B$25)/$B$25 | I41: =$B$16+($C$23-$B$16)*MIN(I38,$B$25)/$B$25 | J41: =$B$16+($C$23-$B$16)*MIN(J38,$B$25)/$B$25 | ... L41: =$B$16+($C$23-$B$16)*MIN(L38,$B$25)/$B$25
A42: SBC-adjusted FCF ($bn) | C42: =C40*C41 | D42: =D40*D41 | E42: =E40*E41 | F42: =F40*F41 | G42: =G40*G41 | H42: =H40*H41 | I42: =I40*I41 | J42: =J40*J41 | ... L42: =L40*L41
A43: Discount factor | C43: =1/(1+$B$13)^C38 | D43: =1/(1+$B$13)^D38 | E43: =1/(1+$B$13)^E38 | F43: =1/(1+$B$13)^F38 | G43: =1/(1+$B$13)^G38 | H43: =1/(1+$B$13)^H38 | I43: =1/(1+$B$13)^I38 | J43: =1/(1+$B$13)^J38 | ... L43: =1/(1+$B$13)^L38
A44: Present value of FCF ($bn) | C44: =C42*C43 | D44: =D42*D43 | E44: =E42*E43 | F44: =F42*F43 | G44: =G42*G43 | H44: =H42*H43 | I44: =I42*I43 | J44: =J42*J43 | ... L44: =L42*L43
...

Sheet QQQ
A1: QQQ: Invesco QQQ Trust (Nasdaq-100)
A2: Blue = input you can change. Black = formula. Green = link to another tab. US$ billions unless stated; per-share values in US$. Earnings-based look-through model; lower confidence than the single-stock tabs.
A4: 1. Inputs
A5: Share price (US$) | B5: 728.95 | C5: Close 14 Oct 2026, Yahoo Finance / StockAnalysis.com
A6: Trailing P/E | B6: 27.91 | C6: Yahoo Finance, 14 Oct 2026: 27.91 (GAAP; inflated by unrealised investment gains)
A7: Forward P/E (reference) | B7: 21.5 | C7: Trefis, Aug 2026: roughly 21.5 to 22 times 12-month forward earnings. Not refreshed.
A8: Required annual return | B8: 0.095 | C8: 10-yr Treasury ~5.2% plus a 4.3 point equity premium
A9: Terminal growth rate | B9: 0.025 | C9: Below long-run nominal GDP growth
A10: Margin of safety | B10: 0.3 | C10: Wider because the earnings inputs are less certain
A11: Trailing earnings per share (US$) | B11: =B5/B6
A12: Forward earnings per share (US$) | B12: =B5/B7
A14: 2. Scenario assumptions
B15: Bear | C15: Base | D15: Bull
A16: Starting earnings per share (US$) | B16: =B11 | C16: =AVERAGE(B16,D16) | D16: =B12
A17: Earnings growth, year 1 | B17: 0.08 | C17: 0.12 | D17: 0.14
A18: Earnings growth, year 10 | B18: 0.035 | C18: 0.05 | D18: 0.06
A19: Cash conversion (FCF after SBC / earnings) | B19: 0.7 | C19: 0.8 | D19: 0.85
A20: Probability | B20: 0.3 | C20: 0.5 | D20: 0.2
A22: 3. Ten-year projection per index share
A23: Bear case | C23: Y1 | D23: Y2 | E23: Y3 | F23: Y4 | G23: Y5 | H23: Y6 | I23: Y7 | J23: Y8 | K23: Y9 | L23: Y10
A24: Year index | C24: 1 | D24: 2 | E24: 3 | F24: 4 | G24: 5 | H24: 6 | I24: 7 | J24: 8 | K24: 9 | L24: 10
A25: Earnings growth | C25: =$B$17+($B$18-$B$17)*(C24-1)/9 | D25: =$B$17+($B$18-$B$17)*(D24-1)/9 | E25: =$B$17+($B$18-$B$17)*(E24-1)/9 | F25: =$B$17+($B$18-$B$17)*(F24-1)/9 | G25: =$B$17+($B$18-$B$17)*(G24-1)/9 | H25: =$B$17+($B$18-$B$17)*(H24-1)/9 | I25: =$B$17+($B$18-$B$17)*(I24-1)/9 | J25: =$B$17+($B$18-$B$17)*(J24-1)/9 | ... L25: =$B$17+($B$18-$B$17)*(L24-1)/9
A26: Earnings per share (US$) | C26: =$B$16*(1+C25) | D26: =C26*(1+D25) | E26: =D26*(1+E25) | F26: =E26*(1+F25) | G26: =F26*(1+G25) | H26: =G26*(1+H25) | I26: =H26*(1+I25) | J26: =I26*(1+J25) | K26: =J26*(1+K25) | L26: =K26*(1+L25)
A27: Free cash flow per share (US$) | C27: =C26*$B$19 | D27: =D26*$B$19 | E27: =E26*$B$19 | F27: =F26*$B$19 | G27: =G26*$B$19 | H27: =H26*$B$19 | I27: =I26*$B$19 | J27: =J26*$B$19 | ... L27: =L26*$B$19
A28: Discount factor | C28: =1/(1+$B$8)^C24 | D28: =1/(1+$B$8)^D24 | E28: =1/(1+$B$8)^E24 | F28: =1/(1+$B$8)^F24 | G28: =1/(1+$B$8)^G24 | H28: =1/(1+$B$8)^H24 | I28: =1/(1+$B$8)^I24 | J28: =1/(1+$B$8)^J24 | ... L28: =1/(1+$B$8)^L24
A29: Present value (US$) | C29: =C27*C28 | D29: =D27*D28 | E29: =E27*E28 | F29: =F27*F28 | G29: =G27*G28 | H29: =H27*H28 | I29: =I27*I28 | J29: =J27*J28 | ... L29: =L27*L28
A32: Base case | C32: Y1 | D32: Y2 | E32: Y3 | F32: Y4 | G32: Y5 | H32: Y6 | I32: Y7 | J32: Y8 | K32: Y9 | L32: Y10
A33: Year index | C33: 1 | D33: 2 | E33: 3 | F33: 4 | G33: 5 | H33: 6 | I33: 7 | J33: 8 | K33: 9 | L33: 10
A34: Earnings growth | C34: =$C$17+($C$18-$C$17)*(C33-1)/9 | D34: =$C$17+($C$18-$C$17)*(D33-1)/9 | E34: =$C$17+($C$18-$C$17)*(E33-1)/9 | F34: =$C$17+($C$18-$C$17)*(F33-1)/9 | G34: =$C$17+($C$18-$C$17)*(G33-1)/9 | H34: =$C$17+($C$18-$C$17)*(H33-1)/9 | I34: =$C$17+($C$18-$C$17)*(I33-1)/9 | J34: =$C$17+($C$18-$C$17)*(J33-1)/9 | ... L34: =$C$17+($C$18-$C$17)*(L33-1)/9
A35: Earnings per share (US$) | C35: =$C$16*(1+C34) | D35: =C35*(1+D34) | E35: =D35*(1+E34) | F35: =E35*(1+F34) | G35: =F35*(1+G34) | H35: =G35*(1+H34) | I35: =H35*(1+I34) | J35: =I35*(1+J34) | K35: =J35*(1+K34) | L35: =K35*(1+L34)
A36: Free cash flow per share (US$) | C36: =C35*$C$19 | D36: =D35*$C$19 | E36: =E35*$C$19 | F36: =F35*$C$19 | G36: =G35*$C$19 | H36: =H35*$C$19 | I36: =I35*$C$19 | J36: =J35*$C$19 | ... L36: =L35*$C$19
A37: Discount factor | C37: =1/(1+$B$8)^C33 | D37: =1/(1+$B$8)^D33 | E37: =1/(1+$B$8)^E33 | F37: =1/(1+$B$8)^F33 | G37: =1/(1+$B$8)^G33 | H37: =1/(1+$B$8)^H33 | I37: =1/(1+$B$8)^I33 | J37: =1/(1+$B$8)^J33 | ... L37: =1/(1+$B$8)^L33
A38: Present value (US$) | C38: =C36*C37 | D38: =D36*D37 | E38: =E36*E37 | F38: =F36*F37 | G38: =G36*G37 | H38: =H36*H37 | I38: =I36*I37 | J38: =J36*J37 | ... L38: =L36*L37
A41: Bull case | C41: Y1 | D41: Y2 | E41: Y3 | F41: Y4 | G41: Y5 | H41: Y6 | I41: Y7 | J41: Y8 | K41: Y9 | L41: Y10
A42: Year index | C42: 1 | D42: 2 | E42: 3 | F42: 4 | G42: 5 | H42: 6 | I42: 7 | J42: 8 | K42: 9 | L42: 10
A43: Earnings growth | C43: =$D$17+($D$18-$D$17)*(C42-1)/9 | D43: =$D$17+($D$18-$D$17)*(D42-1)/9 | E43: =$D$17+($D$18-$D$17)*(E42-1)/9 | F43: =$D$17+($D$18-$D$17)*(F42-1)/9 | G43: =$D$17+($D$18-$D$17)*(G42-1)/9 | H43: =$D$17+($D$18-$D$17)*(H42-1)/9 | I43: =$D$17+($D$18-$D$17)*(I42-1)/9 | J43: =$D$17+($D$18-$D$17)*(J42-1)/9 | ... L43: =$D$17+($D$18-$D$17)*(L42-1)/9
A44: Earnings per share (US$) | C44: =$D$16*(1+C43) | D44: =C44*(1+D43) | E44: =D44*(1+E43) | F44: =E44*(1+F43) | G44: =F44*(1+G43) | H44: =G44*(1+H43) | I44: =H44*(1+I43) | J44: =I44*(1+J43) | K44: =J44*(1+K43) | L44: =K44*(1+L43)
A45: Free cash flow per share (US$) | C45: =C44*$D$19 | D45: =D44*$D$19 | E45: =E44*$D$19 | F45: =F44*$D$19 | G45: =G44*$D$19 | H45: =H44*$D$19 | I45: =I44*$D$19 | J45: =J44*$D$19 | ... L45: =L44*$D$19
A46: Discount factor | C46: =1/(1+$B$8)^C42 | D46: =1/(1+$B$8)^D42 | E46: =1/(1+$B$8)^E42 | F46: =1/(1+$B$8)^F42 | G46: =1/(1+$B$8)^G42 | H46: =1/(1+$B$8)^H42 | I46: =1/(1+$B$8)^I42 | J46: =1/(1+$B$8)^J42 | ... L46: =1/(1+$B$8)^L42
A47: Present value (US$) | C47: =C45*C46 | D47: =D45*D46 | E47: =E45*E46 | F47: =F45*F46 | G47: =G45*G46 | H47: =H45*H46 | I47: =I45*I46 | J47: =J45*J46 | ... L47: =L45*L46
...

Sheet GLD
A1: GLD: SPDR Gold Shares
A2: Reference range only. Gold produces no cash flow, so there is no intrinsic value to compute. Blue = input you can change. Black = formula. Green = link to another tab. US$ billions unless stated; per-share values in US$.
A4: 1. Inputs
A5: GLD share price (US$) | B5: 375.99 | C5: Close 14 Oct 2026, Macrotrends
A6: Ounces of gold per GLD share | B6: 0.0925 | C6: ESTIMATE: about 0.0925 oz after years of fee deductions
A7: Margin of safety | B7: 0.3 | C7: Wide because the range is a judgement, not a calculation
A8: Gold price implied by GLD (US$/oz) | B8: =B5/B6
A10: 2. Scenarios
B11: Bear | C11: Base | D11: Bull
A12: Gold price (US$ per oz) | B12: 3300 | C12: 4100 | D12: 5000
A13: Probability | B13: 0.35 | C13: 0.45 | D13: 0.2
A14: Value per GLD share (US$) | B14: =B12*$B$6 | C14: =C12*$B$6 | D14: =D12*$B$6
A15: Rationale
A16: Scenario description | B16: Real yields stay >2.5%, USD firm; gold reverts toward the inflation-adjusted 1980 peak (~$3,300-3,500). | C16: Range-bound near the 2026 trading range as real yields and central-bank buying offset. | D16: Fed pivots / inflation de-anchors; sell-side targets of $4,900-5,000 are reached.
A18: 3. Reference value
A19: Probability-weighted reference value (US$) | B19: =SUMPRODUCT(B14:D14,B13:D13)
A20: Buy-below reference after margin of safety (US$) | B20: =B19*(1-B7)
A21: Current price (US$) | B21: =B5
A22: Price vs reference value | B22: =B21/B19-1
A23: Status | B23: =IF(B21<=B20,"Below reference range",IF(B21<=B19*(1-B7/2),"Lower half of range",IF(B21<=B19,"Near reference value","Above reference range")))
A25: Scenario gold prices are judgement calls anchored to the 2026 trading range ($4,000 to $4,400), the inflation-adjusted 1980 peak and published sell-side targets. They are not derived from cash flows.

Sheet Sources
A1: Sources
A2: Where each figure came from. Prices and market data as of 14 Oct 2026.
A4: Item | B4: Source
A5: Prices (AAPL, MSFT, GOOGL, AMZN) | B5: StockAnalysis.com price history, S&P Global Market Intelligence data, close 14 Oct 2026
A6: QQQ price and trailing P/E | B6: Yahoo Finance QQQ quote, close 14 Oct 2026 (728.95; trailing P/E 27.91)
A7: QQQ forward P/E | B7: Trefis QQQM valuation page, Aug 2026 (about 21.5x). Not refreshed since.
A8: GLD price | B8: Macrotrends GLD price history, close 14 Oct 2026 (375.99)
A9: Gold price context | B9: Bernama and psuconnect.in, Oct 2026: spot gold roughly $4,100 to $4,220 per oz
A10: Apple financials | B10: Apple 10-Q for the quarter to 27 Jun 2026 (sec.gov); StockAnalysis.com cash flow, TTM Jun 2026
A11: Microsoft financials | B11: StockAnalysis.com FY2026 cash flow and balance sheet; Microsoft Q4 FY2026 earnings call (29 Jul 2026)
A12: Alphabet financials | B12: Alphabet Q2 2026 earnings release and 10-Q (sec.gov); StockAnalysis.com balance sheet
A13: Amazon financials | B13: Amazon Q2 2026 earnings release and 10-Q (sec.gov); StockAnalysis.com balance sheet
A14: Treasury yields and Fed | B14: Trading Economics (9 Oct 2026); roic.ai (13 Oct 2026): 10-year yield about 5.2%
